Workbook

Sheet MATRIZ
A1: TRADE | B1: MARCA/SEGMENTO | C1: NOMBRE CAMPAÑA AGRUPADA VISIBILITY | D1: FECHA DE INICIO CAMPAÑA | E1: FECHA MÁX. IMPLEMENTACIÓN | F1: FECHA DE TERMINO CAMPAÑA | G1: FECHA DE TERMINO IMPLEMENTACION | H1: NOMBRE CAMPAÑA INDIVIDUAL VISIBILITY | I1: ID
A2: Carmen Contardo | D2: 44965 | F2: 45024 | G2: 45024 | H2: W02 JUMBO STOPPER 20X50 BANDEO NIDO 1+
A3: Carmen Contardo | D3: 44965 | F3: 45024 | G3: 45024 | H3: W02 SISA STOPPER 20X50 BANDEO NIDO 1+
A4: Carmen Contardo | C4: CAVERNICOLAS | D4: 44942 | F4: 45012 | G4: 45012 | H4: W02 JUMBO CAVERNICOLAS FLEJERA + STOPPER + VIBRIN
A5: Carmen Contardo | C5: CAVERNICOLAS | D5: 44942 | F5: 45012 | G5: 45012 | H5: W02 JUMBO CAVERNICOLAS FLEJERA + STOPPER + VIBRIN
A6: Carmen Contardo | C6: CAVERNICOLAS | D6: 44942 | F6: 45012 | G6: 45012 | H6: W02 JUMBO CAVERNICOLAS FLEJERA + STOPPER + VIBRIN
A7: Carmen Contardo | C7: CAVERNICOLAS | D7: 44942 | F7: 45012 | G7: 45012 | H7: W02 SISA CAVERNICOLAS FLEJERA + STOPPER + VIBRIN
A8: Carmen Contardo | C8: CAVERNICOLAS | D8: 44942 | F8: 45012 | G8: 45012 | H8: W02 SISA CAVERNICOLAS FLEJERA + STOPPER + VIBRIN
A9: Carmen Contardo | C9: CAVERNICOLAS | D9: 44942 | F9: 45012 | G9: 45012 | H9: W02 SISA CAVERNICOLAS FLEJERA + STOPPER + VIBRIN
A10: Carmen Contardo | C10: CAVERNICOLAS | D10: 44942 | F10: 45012 | G10: 45012 | H10: W02 SSRR CAVERNICOLAS FLEJERA + STOPPER + VIBRIN
A11: Carmen Contardo | C11: CAVERNICOLAS | D11: 44942 | F11: 45012 | G11: 45012 | H11: W02 SSRR CAVERNICOLAS FLEJERA + STOPPER + VIBRIN
A12: Carmen Contardo | C12: CAVERNICOLAS | D12: 44942 | F12: 45012 | G12: 45012 | H12: W02 SSRR CAVERNICOLAS FLEJERA + STOPPER + VIBRIN
A13: Roberto Machuca | C13: PASCUA 2023 | D13: 44958 | F13: 45025 | G13: 45025 | H13: W05 TOTTUS PASCUA 2023 - MUEBLE
A14: Roberto Machuca | C14: PASCUA 2023 | D14: 44963 | F14: 45025 | G14: 45025 | H14: W05 ALVI PASCUA 2023 - MUEBLE
A15: Carmen Contardo | C15: BTS | D15: 44972 | F15: 45008 | G15: 45008 | H15: W05 LIDER - LIDER EXPRESS MILO BTS REVESTIMIENTOS + CABECERAS
... A17: Carmen Contardo | C17: BTS | D17: 44978 | F17: 45012 | G17: 45012 | H17: W05 SISA MILO BTS BOMBILLIN MILO TRENCITO
A18: Rosario Larrain | D18: 44972 | F18: 45008 | G18: 45008 | H18: W07 LIDER PAYLOADER CALDO PACK
A19: Rosario Larrain | D19: 44972 | F19: 45008 | G19: 45008 | H19: W07 LIDER STICKERS 2X1000
A20: Rosario Larrain | D20: 44972 | F20: 45008 | G20: 45008 | H20: W07 ACUENTA PAYLOADER GENERICO 5 BANDEJAS +
A21: Rosario Larrain | D21: 44972 | F21: 45008 | G21: 45008 | H21: W07 ACUENTA GRAFICA NESCAFE 3N EN 1 Y MIXES
A22: Rosario Larrain | D22: 44978 | F22: 45012 | G22: 45012 | H22: W05 LIDER PAYLOADER PARA TODO LO RICO
A23: Rosario Larrain | D23: 44978 | F23: 45012 | G23: 45012 | H23: W05 SISA PAYLOADER CALDO PACK
A24: Rosario Larrain | D24: 44972 | F24: 45008 | G24: 45008 | H24: W06 ACUENTA REVESTIMIENTO ISLA MANJAR
A25: Rosario Larrain | D25: 44972 | F25: 45008 | G25: 45008 | H25: W06 LIDER REVESTIMIENTO ISLA MANJAR
A26: Rosario Larrain | D26: 44972 | F26: 45008 | G26: 45008 | H26: W06 LIDER EXPRESS REVESTIMIENTO CABECERA CAFE
A27: Rosario Larrain | D27: 44972 | F27: 45008 | G27: 45008 | H27: W06 ACUENTA REVESTIMIENTO CABECERA E ISLA CAFE
A28: Rosario Larrain | D28: 44972 | F28: 45008 | G28: 45008 | H28: W06 LIDER REVESTIMIENTO CABECERA E ISLA CAFE
A29: Roberto Machuca | C29: PASCUA 2023 | D29: 44972 | F29: 45025 | G29: 45025 | H29: W06 MAYORISTA 10 PASCUA 2023 - BOTADERO + MUEBLE PAYLOADEAR
A30: Roberto Machuca | C30: PASCUA 2023 | D30: 44972 | F30: 45025 | G30: 45025 | H30: W06 UNIMARC PASCUA 2023 - BOTADERO + MUEBLE PAYLOADEAR
A31: Roberto Machuca | C31: PASCUA 2023 | D31: 44972 | F31: 45025 | G31: 45025 | H31: W06 SSRR PASCUA 2023 - BOTADERO + MUEBLE PAYLOADEAR
A32: Roberto Machuca | C32: PASCUA 2023 | D32: 44984 | F32: 45025 | G32: 45025 | H32: W07 SSRR PASCUA 2023 - MUEBLE PAYLOADEAR TRENCITO
A33: Roberto Machuca | C33: PASCUA 2023 | D33: 44984 | F33: 45025 | G33: 45025 | H33: W06 SMU PASCUA 2023 - MUEBLES QW
A34: Roberto Machuca | C34: PASCUA 2023 | D34: 44984 | F34: 45025 | G34: 45025 | H34: W06 TOTTUS PASCUA 2023 - MUEBLES QW
A35: Roberto Machuca | C35: PASCUA 2023 | D35: 44999 | F35: 45025 | G35: 45025 | H35: W07 JUMBO PASCUA 2023 - MUEBLE EXHIBICION MEDIO + COMPLETO
A36: Andrea Gonzalez | D36: 45007 | F36: 45040 | G36: 45020 | H36: W12 ALVI - CUBREPALLET GRILL
A37: Carmen Contardo | D37: 45019 | F37: 45080 | G37: 45030 | H37: W14 SSRR - MOUSSE
A38: Roberto Machuca | C38: PASCUA 2023 | D38: 44999 | F38: 45025 | G38: 45012 | H38: W11 SISA PASCUA 2023 - EXHIBIDORES + BOTADEROS
A39: Carmen Contardo | C39: BTS PIXAR | D39: 45017 | F39: 45046 | G39: 45030 | H39: W13 SISA - BTS PIXAR
A40: Carmen Contardo | C40: BTS PIXAR | D40: 45017 | F40: 45046 | G40: 45030 | H40: W13 JUMBO - BTS PIXAR
A41: Carmen Contardo | C41: BTS PIXAR | D41: 45013 | F41: 45040 | G41: 45026 | H41: W13 SSRR - BTS PIXAR
...

Sheet Hoja2
G1: TRADE | I1: ID | L1: ID | M1: NOMBRE | P1: MARCA/SEGMENTO | Q1: id
G2: Amanda Diaz | H2: =UPPER(G2) -> AMANDA DIAZ | I2: =_xlfn.XLOOKUP(H2,M:M,L:L) -> 1 | L2: 1 | M2: AMANDA DIAZ | P2: Chocolates | Q2: =_xlfn.XLOOKUP(P2,T:T,S:S) -> 3
G3: Joaquin Marzan | H3: =UPPER(G3) -> JOAQUIN MARZAN | I3: =_xlfn.XLOOKUP(H3,M:M,L:L) -> 2 | L3: 2 | M3: JOAQUIN MARZAN | P3: Onefood | Q3: =_xlfn.XLOOKUP(P3,T:T,S:S) -> 4 | S3: 1 | T3: JUGUETERIA | U3: GENERALMENTE ASOCIADO A HASBRO | V3: 1 | W3: 46205.596 | X3: 46205.596
G4: Maria Emilia Fuenzalida | H4: =UPPER(G4) -> MARIA EMILIA FUENZALIDA | I4: =_xlfn.XLOOKUP(H4,M:M,L:L) -> 3 | L4: 3 | M4: MARIA EMILIA FUENZALIDA | P4: Galletas | Q4: =_xlfn.XLOOKUP(P4,T:T,S:S) -> 5 | S4: 2 | T4: LIMPIEZA | U4: ASOCIADO A MATERIAL DE HIGIENE | V4: 1 | W4: 46205.597 | X4: 46205.597
G5: Emilia Fuenzalida | H5: =UPPER(G5) -> EMILIA FUENZALIDA | I5: =_xlfn.XLOOKUP(H5,M:M,L:L) -> 4 | L5: 4 | M5: EMILIA FUENZALIDA | P5: Nutrición | Q5: 6 | S5: 3 | T5: CHOCOLATES | V5: 1 | W5: 46205.613 | X5: 46205.613
G6: Maria Ignacia Ariztia | H6: =UPPER(G6) -> MARIA IGNACIA ARIZTIA | I6: =_xlfn.XLOOKUP(H6,M:M,L:L) -> 5 | L6: 5 | M6: MARIA IGNACIA ARIZTIA | P6: Helados | Q6: =_xlfn.XLOOKUP(P6,T:T,S:S) -> 7 | S6: 4 | T6: ONEFOOD | V6: 1 | W6: 46205.613 | X6: 46205.613
G7: Francisco Jordan | H7: =UPPER(G7) -> FRANCISCO JORDAN | I7: =_xlfn.XLOOKUP(H7,M:M,L:L) -> 6 | L7: 6 | M7: FRANCISCO JORDAN | P7: Multicategoria | Q7: =_xlfn.XLOOKUP(P7,T:T,S:S) -> 8 | S7: 5 | T7: GALLETAS | V7: 1 | W7: 46205.613 | X7: 46205.613
P8: LLCC | Q8: =_xlfn.XLOOKUP(P8,T:T,S:S) -> 9 | S8: 6 | T8: NUTRICION | V8: 1 | W8: 46205.613 | X8: 46205.613
P9: CAFÉ | Q9: 10 | S9: 7 | T9: HELADOS | V9: 1 | W9: 46205.613 | X9: 46205.613
P10: Culinarios | Q10: =_xlfn.XLOOKUP(P10,T:T,S:S) -> 11 | S10: 8 | T10: MULTICATEGORIA | V10: 1 | W10: 46205.613 | X10: 46205.613
P11: Yogur Batido Nestlé | Q11: 12 | S11: 9 | T11: LLCC | V11: 1 | W11: 46205.613 | X11: 46205.613
P12: Mixes | Q12: =_xlfn.XLOOKUP(P12,T:T,S:S) -> 13 | S12: 10 | T12: CAFE | V12: 1 | W12: 46205.613 | X12: 46205.613
P13: Refrigerados | Q13: =_xlfn.XLOOKUP(P13,T:T,S:S) -> 14 | S13: 11 | T13: CULINARIOS | V13: 1 | W13: 46205.613 | X13: 46205.613
P14: Maggi | Q14: =_xlfn.XLOOKUP(P14,T:T,S:S) -> 15 | S14: 12 | T14: YOGUR BATIDO NESTLE | V14: 1 | W14: 46205.614 | X14: 46205.614
S15: 13 | T15: MIXES | V15: 1 | W15: 46205.614 | X15: 46205.614
S16: 14 | T16: REFRIGERADOS | V16: 1 | W16: 46205.616 | X16: 46205.616
S17: 15 | T17: MAGGI | V17: 1 | W17: 46205.616 | X17: 46205.616

Sheet AGRUPADO
A1: NOMBRE CAMPAÑA VISIBILITY | B1: NOMBRE CAMPAÑA AGRUPADA
A2: W47 UNIMARC - BOTADEROS MCKAY (BOTADERO) | B2: GALLETAS MCKAY BOTADERO
A3: W46 HIPER LIDER - HOTSPOT TRENCITO BAÑADA (HOTSPOT) | B3: GALLETA TRENCITO BAÑADA
A4: W46 MAYORISTA 10 - MUEBLES GALLETAS NAVIDAD (PAYLOADERS) | B4: GALLETAS NAVIDAD
A5: W46 UNIMARC - MUEBLES NAVIDAD (PAYLOADERS) | B5: GALLETAS NAVIDAD
A6: W47 HIPER LIDER - POP NIDO TRANSFORMACIÓN (STOPPER) | B6: NIDO TRANSFORMACION
A7: W47 LIDER EXPRESS - POP NIDO TRANSFORMACIÓN (STOPPER) | B7: NIDO TRANSFORMACION
A8: W47 UNIMARC - POP NIDO TRANSFORMACIÓN (STOPPER) | B8: NIDO TRANSFORMACION
A9: W48 JUMBO - POP NIDO TRANSFORMACIÓN (FLEJERA L) | B9: NIDO TRANSFORMACION
A10: W48 JUMBO - POP NIDO TRANSFORMACIÓN (STOPPER VIBRIN) | B10: NIDO TRANSFORMACION
A11: W48 SISA - POP NIDO TRANSFORMACIÓN (FLEJERA L) | B11: NIDO TRANSFORMACION
A12: W48 SISA - POP NIDO TRANSFORMACIÓN (STOPPER VIBRIN) | B12: NIDO TRANSFORMACION
... A139: W9 SISA - PAYLOADERS MAGGI (PAYLOADER) | B139: MAGGI
A140: ='[1]PANEL DE CONTROL'!R650 -> W8 FARMACIA INDEPENDIENTE - MATERIAL (PAYLOADER) | B140: FARMACIA INDEPENDIENTE
A141: ='[1]PANEL DE CONTROL'!R651 -> W8 FARMACIA INDEPENDIENTE - MATERIAL (ANTIBRECHA) | B141: FARMACIA INDEPENDIENTE
A142: ='[1]PANEL DE CONTROL'!R652 -> W8 FARMACIA INDEPENDIENTE - MATERIAL (DESCOLOCADOR DE ALARMAS) | B142: FARMACIA INDEPENDIENTE
A143: ='[1]PANEL DE CONTROL'!R653 -> W8 FARMACIA INDEPENDIENTE - MATERIAL (ALARMAS) | B143: FARMACIA INDEPENDIENTE
A144: ='[1]PANEL DE CONTROL'!R654 -> W9 HIPER LIDER - LISTA 2 PAYLOADER TRENCITO SN(PAYLOADER) | B144: LISTA 2 TRENCITO SN
A145: ='[1]PANEL DE CONTROL'!R655 -> W9 LIDER EXPRESS - LISTA 2 PAYLOADER TRENCITO SN(PAYLOADER) | B145: LISTA 2 TRENCITO SN
A146: ='[1]PANEL DE CONTROL'!R656 -> W7 HIPER LIDER - NIDO BTS (REVESTIMIENTO) | B146: NIDO BTS
A147: ='[1]PANEL DE CONTROL'!R657 -> W7 HIPER LIDER - NIDO BTS (PAYLOADER) | B147: NIDO BTS
A148: ='[1]PANEL DE CONTROL'!R658 -> W7 HIPER LIDER - NIDO BTS (STICKER QR) | B148: NIDO BTS
A149: ='[1]PANEL DE CONTROL'!R659 -> W7 LIDER EXPRESS - NIDO BTS (REVESTIMIENTO) | B149: NIDO BTS
A150: ='[1]PANEL DE CONTROL'!R660 -> W7 LIDER EXPRESS - NIDO BTS (STICKER QR) | B150: NIDO BTS
A151: ='[1]PANEL DE CONTROL'!R661 -> W9 SSRR - BICICLETAS Y MATERIAL PARA CONCURSO (BICICLETA) | B151: MILO CONCURSO
A152: ='[1]PANEL DE CONTROL'!R661 -> W9 SSRR - BICICLETAS Y MATERIAL PARA CONCURSO (BICICLETA) | B152: MILO CONCURSO
A153: ='[1]PANEL DE CONTROL'!R662 -> W9 SSRR - BICICLETAS Y MATERIAL PARA CONCURSO (REVESTIMIENTO ISLA) | B153: MILO CONCURSO
A154: ='[1]PANEL DE CONTROL'!R663 -> W9 SSRR - BICICLETAS Y MATERIAL PARA CONCURSO (REVESTIMIENTO LATERAL DE CABECERA) | B154: MILO CONCURSO
A155: ='[1]PANEL DE CONTROL'!R663 -> W9 SSRR - BICICLETAS Y MATERIAL PARA CONCURSO (REVESTIMIENTO LATERAL DE CABECERA) | B155: MILO CONCURSO
A156: ='[1]PANEL DE CONTROL'!R664 -> W9 SSRR - BICICLETAS Y MATERIAL PARA CONCURSO (STOPPER VIBRIN) | B156: MILO CONCURSO
A157: ='[1]PANEL DE CONTROL'!R665 -> W9 SSRR - BICICLETAS Y MATERIAL PARA CONCURSO (STOPPER VIBRIN) | B157: MILO CONCURSO
A158: ='[1]PANEL DE CONTROL'!R666 -> W9 SSRR - BICICLETAS Y MATERIAL PARA CONCURSO (BANDEJA EN L) | B158: MILO CONCURSO
A159: ='[1]PANEL DE CONTROL'!R667 -> W9 SSRR - BICICLETAS Y MATERIAL PARA CONCURSO (PENDON) | B159: MILO CONCURSO
A160: ='[1]PANEL DE CONTROL'!R668 -> W9 SSRR - BICICLETAS Y MATERIAL PARA CONCURSO (CUPONERA CONCURSO) | B160: MILO CONCURSO
A161: ='[1]PANEL DE CONTROL'!R669 -> W9 SSRR - BICICLETAS Y MATERIAL PARA CONCURSO (BUZON) | B161: MILO CONCURSO
A162: ='[1]PANEL DE CONTROL'!R670 -> W9 JUMBO - NESTLÉ PASCUA 2024(EXHIBICION COMPLETA) | B162: PASCUA 2024
A163: ='[1]PANEL DE CONTROL'!R671 -> W9 JUMBO - NESTLÉ PASCUA 2024(EXHIBICION MEDIA) | B163: PASCUA 2024
A164: ='[1]PANEL DE CONTROL'!R672 -> W9 TOTTUS - MATERIALES CERELAC (GANCHERA) | B164: CERELAC
A165: ='[1]PANEL DE CONTROL'!R673 -> W9 TOTTUS - MATERIALES CERELAC (BANDEJA) | B165: CERELAC
A166: ='[1]PANEL DE CONTROL'!R674 -> W11 HIPER LIDER - ISLAS NESTLÉ RENUEVA TU CASA (ISLA) | B166: RENUEVA TU CASA
...

Sheet Hoja1
G1: id | H1: nombre
G2: 1655 | H2: REGISTRO DE GESTIONES ADICIONALES ABL
G3: 2270 | H3: W50 HIPER LIDER - MILO (PAYLOADER)
G4: 2297 | H4: W02 MAYORISTA 10 - PAYLOADER TUCO (PAYLOADER AB)
G5: 2300 | H5: UNIMARC PAYLOADER AB
G6: 2304 | H6: W02 SSRR - TRITON LOLLAPALOOZA(PAYLOADER)
G7: 2307 | H7: W02 UNIMARC - NATURNES (PAYLOADER)
G8: 2309 | H8: W02 UNIMARC - PAYLOADER TUCO (PAYLOADER AB)
G9: 2321 | H9: W02 SUPER 10 - PAYLOADER TUCO (PAYLOADER AB)
G10: 2322 | H10: W02 JUMBO - TRITON LOLLAPALOOZA (HOTSPOT)
G11: 2323 | H11: W02 SISA - TRITON LOLLAPALOOZA (HOTSPOT)
G12: 2324 | H12: W02 TOTTUS - TRITON LOLLAPALOOZA (HOTSPOT)
G13: 2325 | H13: W02 WALMART - TRITON LOLLAPALOOZA (HOTSPOT)
... G41: 2398 | H41: W04 SISA - CREMA SIN LACTOSA (STOPPER SISA)
G42: 2399 | H42: W04 WALMART - STARBUCKS (PAYLOADER) | I42: W04 WALMART - STARBUCKS (PAYLOADER) | J42: =I42=H42 -> TRUE
G43: 2400 | H43: W04 WALMART - STARBUCKS (QR)
G44: 2401 | H44: W04 WALMART - LECHE SUR (PAYLOADER)
G45: 2402 | H45: W04 WALMART - LECHE SUR (QR)
G46: 2403 | H46: W04 SSRR - TRITON LOLLAPALOOZA (PAYLOADER)
G47: 2405 | H47: W04 SSRR - CAMPAÑA CORPORATIVA ENERO 2026
G48: 2415 | H48: W05 SISA - NATURNES (PAYLOADER)
G49: 2416 | H49: W05 SISA - NATURNES (QR)
G50: 2417 | H50: W05 SISA CAMPAÑA AUDITORIA - TRITONAZO (HOTSPOT) ENERO 2026
G51: 2435 | H51: W06 SSRR - DIA DE LOS ENAMORADOS (PAYLOADER)
G52: 2436 | H52: W06 SISA - DIA DE LOS ENAMORADOS (PAYLOADER)
G53: 2437 | H53: W06 JUMBO - DIA DE LOS ENAMORADOS (ISLA)
G54: 2438 | H54: W06 SSRR - DIA DE LOS ENAMORADOS (PAYLOADER)
... G178: 2846 | H178: W26 SPID - CUBRE REFRI SPID (CUBRE REFRI)
